# <center/>Exception #
###1.概述###
####Python使用被称为异常的特殊对象来管理程序执行期间发生的错误。每当发生让Python不知所措的错误时，它都会创建一个异常对象。如果你编写了处理该异常的代码，程序将继续运行；如果你未对异常进行处理，程序将停止，并显示一个traceback，其中包含有关异常的报告。异常是使用try-except代码块处理的。try-except代码块让Python执行指定的操作，同时告诉Python发生异常时怎么办。####
###2.try-except 代码块###
####如果try代码块中的代码运行起来没有问题，Python将跳过except代码块；如果try代码块中的代码导致了错误，Python将查找这样的except代码块，并运行其中的代码。####
###3.else 代码块代码块###
#### 将可能引发错误的代码放在try-except代码块中；依赖于try代码块成功执行的代码都应放到else代码块中。#### 
####try-except-else代码块的工作原理大致如下：Python尝试执行try代码块中的代码；只有可能引发异常的代码才需要放在try语句中。有时候，有一些仅在try代码块成功执行时才需要运行的代码；这些代码应放在else代码块中。except代码块告诉Python，如果它尝试运行try代码块中的代码时引发了指定的异常，该怎么办。但并非每次捕获到异常时都需要告诉用户，有时候你希望程序在发生异常时一声不吭，就像什么都没有发生一样继续运行。要让程序在失败时一声不吭，可像通常那样编写try代码块，但在except代码块中明确地告诉Python什么都不要做。Python有一个pass语句，可在代码块中使用它来让Python什么都不要做。####
		file1="cats.txt"
		file2="dogs.txt"
		
		def  Print(file_name):
			try :
				with open(file_name) as file_object:
					content=file_object.read()
			except  IOError:
				#print "File "+file_name+" not found!"
				pass
			else:
				print content.rstrip()
				
		def CountWords(file_name):
			try :
				with open(file_name) as file_object:
					content=file_object.read()
			except  IOError:
				#print "File "+file_name+" not found!"
				pass
			else:
				print len(content.rstrip())
				print content.rstrip().lower().count("the") #查找程序中的the的数量
				
		files=['cats.txt','dogs.txt','A Little Princess .txt']
		
		for file  in  files:
			CountWords(file)
			print"================="
			
		
